Workbook

Sheet How to Use
A1: MARKETING AUDIT SCORECARD | NorCal SBDC
A3: PURPOSE
A4: This scorecard gives you a structured, data-informed baseline of a client's current marketing
A5: across 8 dimensions. Use it during or after your first session.
A7: HOW TO SCORE
A8: Score | B8: Meaning
A9: 0 | B9: Not present / never done
A10: 1 | B10: Minimal / very basic attempt
A11: 2 | B11: Partially in place — needs work
A12: 3 | B12: Solid but could be improved
A13: 4 | B13: Well done — strong execution
A14: 5 | B14: Excellent — best practice level
A16: WORKFLOW
A17: Step 1 | B17: Fill in client info at the top of the Audit tab
A18: Step 2 | B18: Score each criterion 0–5 using the drop-down
A19: Step 3 | B19: Add notes on what you observed or the client shared
A20: Step 4 | B20: Review the Dashboard tab for auto-calculated scores
A21: Step 5 | B21: Use the Priority column to flag the top 3 areas to work on
A23: SCORE INTERPRETATION (Dashboard)
A24: 0–39% | B24: Critical — foundational gaps, start from scratch
A25: 40–59% | B25: Developing — basic presence, needs strategic work
A26: 60–74% | B26: Functional — decent foundation, optimize & expand
A27: 75–89% | B27: Strong — well-rounded, focus on highest-impact gaps
A28: 90–100% | B28: Advanced — maintain and innovate

Sheet Audit
A1: MARKETING AUDIT SCORECARD | NorCal SBDC
A2: Client / Business: | E2: Advisor:
A3: Date: | E3: Industry:
A4: # | B4: Criterion | C4: Advisor Guidance | D4: Score (0–5) | E4: Max | F4: Priority | G4: Notes / Observations
A5: 1. Website & Online Presence
A6: 1 | B6: Website exists and is mobile-friendly | C6: Check on phone — loads fast, easy to navigate? | D6: 0 | E6: 5 | F6: —
A7: 2 | B7: Website clearly explains what they sell | C7: Can a stranger understand in 10 seconds? | D7: 0 | E7: 5 | F7: —
A8: 3 | B8: Clear call-to-action on homepage | C8: Phone number, contact form, buy now, book, etc. | D8: 0 | E8: 5 | F8: —
A9: 4 | B9: Website has been updated in the last 6 months | C9: Check blog, products, hours, or news section | D9: 0 | E9: 5 | F9: —
A10: 5 | B10: SSL certificate / secure site (https://) | C10: Lock icon in browser bar — essential for trust | D10: 0 | E10: 5 | F10: —
A11: 1. Website & Online Presence — Subtotal | D11: =SUM(D6:D10) -> 0 | E11: =SUM(E6:E10) -> 25 | F11: =IFERROR(D11/E11,0) -> 0
A13: 2. Search Engine Optimization (SEO)
A14: 1 | B14: Google Business Profile is claimed & complete | C14: Hours, photos, description, category all filled in | D14: 0 | E14: 5 | F14: —
A15: 2 | B15: Business shows in local search results | C15: Search "[business type] near [city]" — do they appear? | D15: 0 | E15: 5 | F15: —
A16: 3 | B16: Website has basic on-page SEO | C16: Title tags, meta descriptions, keyword usage | D16: 0 | E16: 5 | F16: —
A17: 4 | B17: Customer reviews present on Google / Yelp | C17: 10+ reviews with a 4.0+ average is a good benchmark | D17: 0 | E17: 5 | F17: —
A18: 5 | B18: NAP consistency (Name, Address, Phone) | C18: Same info across Google, Yelp, website, social | D18: 0 | E18: 5 | F18: —
A19: 2. Search Engine Optimization (SEO) — Subtotal | D19: =SUM(D14:D18) -> 0 | E19: =SUM(E14:E18) -> 25 | F19: =IFERROR(D19/E19,0) -> 0
A21: 3. Social Media
A22: 1 | B22: Active on at least one platform | C22: Posted in the last 30 days? | D22: 0 | E22: 5 | F22: —
A23: 2 | B23: Profile is complete with bio and contact info | C23: Photo, description, link to website | D23: 0 | E23: 5 | F23: —
A24: 3 | B24: Content is relevant to their target audience | C24: Would their ideal customer find it valuable? | D24: 0 | E24: 5 | F24: —
A25: 4 | B25: Engagement rate is reasonable | C25: Likes/comments relative to follower count — not ghost followers | D25: 0 | E25: 5 | F25: —
A26: 5 | B26: Consistent posting frequency | C26: At least 1–2x per week on primary platform | D26: 0 | E26: 5 | F26: —
A27: 3. Social Media — Subtotal | D27: =SUM(D22:D26) -> 0 | E27: =SUM(E22:E26) -> 25 | F27: =IFERROR(D27/E27,0) -> 0
A29: 4. Email Marketing
A30: 1 | B30: Email list exists (any size) | C30: Even a small list is an owned asset — no list = 0 | D30: 0 | E30: 5 | F30: —
A31: 2 | B31: Sends emails at least monthly | C31: Consistency matters more than frequency | D31: 0 | E31: 5 | F31: —
A32: 3 | B32: Emails have clear subject lines & CTA | C32: Would you open this? Is there one clear next step? | D32: 0 | E32: 5 | F32: —
A33: 4 | B33: Unsubscribe and legal compliance in place | C33: CAN-SPAM / GDPR basics — unsubscribe link present | D33: 0 | E33: 5 | F33: —
A34: 5 | B34: Tracks open rates or click rates | C34: Any platform shows this — do they review it? | D34: 0 | E34: 5 | F34: —
A35: 4. Email Marketing — Subtotal | D35: =SUM(D30:D34) -> 0 | E35: =SUM(E30:E34) -> 25 | F35: =IFERROR(D35/E35,0) -> 0
A37: 5. Content & Messaging
A38: 1 | B38: Clear and consistent brand voice | C38: Same tone across website, social, email, in-person | D38: 0 | E38: 5 | F38: —
A39: 2 | B39: Unique value proposition is defined | C39: Can they state it in one sentence? | D39: 0 | E39: 5 | F39: —
A40: 3 | B40: Customer testimonials or social proof visible | C40: Reviews, case studies, before/after, logos | D40: 0 | E40: 5 | F40: —
A41: 4 | B41: Content addresses customer pain points | C41: Does their messaging speak to what customers need? | D41: 0 | E41: 5 | F41: —
A42: 5 | B42: Visual identity is consistent | C42: Logo, colors, fonts used the same way everywhere | D42: 0 | E42: 5 | F42: —
A43: 5. Content & Messaging — Subtotal | D43: =SUM(D38:D42) -> 0 | E43: =SUM(E38:E42) -> 25 | F43: =IFERROR(D43/E43,0) -> 0
A45: 6. Paid Advertising
...

Sheet Dashboard
A1: MARKETING AUDIT | SCORE DASHBOARD
A2: Client: | D2: =Audit!C2 -> 0
A4: OVERALL SCORE | B4: Score | D4: Max | E4: % Score | F4: Rating
A5: Total (All Categories) | B5: =Audit!D69 -> 0 | D5: =Audit!E69 -> 400 | E5: =IFERROR(B5/D5,0) -> 0 | F5: =IF(E5>=0.9,"Advanced ⭐",IF(E5>=0.75,"Strong ✅",IF(E5>=0.6,"Functional 🔧",IF(E5>=0.4,"Developing 📈","Critical 🚨")))) -> Critical 🚨
A7: CATEGORY BREAKDOWN | B7: Score | D7: Max | E7: % Score | F7: Priority Focus?
A8: 1. Website & Online Presence | B8: =Audit!D11 -> 0 | D8: =Audit!E11 -> 25 | E8: =IFERROR(B8/D8,0) -> 0 | F8: =IF(E8>=0.8,"Strong ✅",IF(E8>=0.6,"Good 🔧",IF(E8>=0.4,"Needs Work 📈","Priority 🚨"))) -> Priority 🚨
A9: 2. Search Engine Optimization (SEO) | B9: =Audit!D19 -> 0 | D9: =Audit!E19 -> 25 | E9: =IFERROR(B9/D9,0) -> 0 | F9: =IF(E9>=0.8,"Strong ✅",IF(E9>=0.6,"Good 🔧",IF(E9>=0.4,"Needs Work 📈","Priority 🚨"))) -> Priority 🚨
A10: 3. Social Media | B10: =Audit!D27 -> 0 | D10: =Audit!E27 -> 25 | E10: =IFERROR(B10/D10,0) -> 0 | F10: =IF(E10>=0.8,"Strong ✅",IF(E10>=0.6,"Good 🔧",IF(E10>=0.4,"Needs Work 📈","Priority 🚨"))) -> Priority 🚨
A11: 4. Email Marketing | B11: =Audit!D35 -> 0 | D11: =Audit!E35 -> 25 | E11: =IFERROR(B11/D11,0) -> 0 | F11: =IF(E11>=0.8,"Strong ✅",IF(E11>=0.6,"Good 🔧",IF(E11>=0.4,"Needs Work 📈","Priority 🚨"))) -> Priority 🚨
A12: 5. Content & Messaging | B12: =Audit!D43 -> 0 | D12: =Audit!E43 -> 25 | E12: =IFERROR(B12/D12,0) -> 0 | F12: =IF(E12>=0.8,"Strong ✅",IF(E12>=0.6,"Good 🔧",IF(E12>=0.4,"Needs Work 📈","Priority 🚨"))) -> Priority 🚨
A13: 6. Paid Advertising | B13: =Audit!D51 -> 0 | D13: =Audit!E51 -> 25 | E13: =IFERROR(B13/D13,0) -> 0 | F13: =IF(E13>=0.8,"Strong ✅",IF(E13>=0.6,"Good 🔧",IF(E13>=0.4,"Needs Work 📈","Priority 🚨"))) -> Priority 🚨
A14: 7. Customer Retention & Loyalty | B14: =Audit!D59 -> 0 | D14: =Audit!E59 -> 25 | E14: =IFERROR(B14/D14,0) -> 0 | F14: =IF(E14>=0.8,"Strong ✅",IF(E14>=0.6,"Good 🔧",IF(E14>=0.4,"Needs Work 📈","Priority 🚨"))) -> Priority 🚨
A15: 8. Analytics & Measurement | B15: =Audit!D67 -> 0 | D15: =Audit!E67 -> 25 | E15: =IFERROR(B15/D15,0) -> 0 | F15: =IF(E15>=0.8,"Strong ✅",IF(E15>=0.6,"Good 🔧",IF(E15>=0.4,"Needs Work 📈","Priority 🚨"))) -> Priority 🚨
A17: TOP PRIORITY AREAS (Advisor Notes)
A18: Priority #1
A19: Priority #2
A20: Priority #3
A22: RECOMMENDED NEXT STEPS
A23: Step 1
A24: Step 2
A25: Step 3
A26: Step 4
